<?xml version="1.0" encoding="utf-8"?>
<!-- This URDF was automatically created by SolidWorks to URDF Exporter! Originally created by Stephen Brawner (brawner@gmail.com) 
     Commit Version: 1.6.0-4-g7f85cfe  Build Version: 1.6.7995.38578
     For more information, please see http://wiki.ros.org/sw_urdf_exporter -->
<robot
  name="bogie_description">
  <link name="base_footprint"/>
  <joint name="base_link_joint" type="fixed">
    <origin xyz="0.0 0.0 0.0" rpy="0 0 0"/>
    <parent link="base_footprint"/>
    <child link="base_link"/>
    <axis xyz="0.0 0.0 0.0"/>
  </joint>
  <link
    name="base_link">
    <inertial>
      <origin
        xyz="-0.0156 -2.5682E-18 0.09256"
        rpy="0 0 0" />
      <mass
        value="3.9475" />
      <inertia
        ixx="0.012826"
        ixy="-2.5056E-19"
        ixz="0.0028353"
        iyy="0.024071"
        iyz="-3.0546E-19"
        izz="0.026102" />
    </inertial>
    <visual>
      <origin
        xyz="0 0 0"
        rpy="0 0 0" />
      <geometry>
        <mesh
          filename="package://bogie_description/meshes/base_link.STL" />
      </geometry>
      <material
        name="">
        <color
          rgba="0.52941 0.54902 0.54902 1" />
      </material>
    </visual>
    <collision>
      <origin
        xyz="0 0 0"
        rpy="0 0 0" />
      <geometry>
        <mesh
          filename="package://bogie_description/meshes/base_link.STL" />
      </geometry>
    </collision>
  </link>
  <link
    name="wheel_1_link">
    <inertial>
      <origin
        xyz="-2.1645E-08 0.00016001 -1.065E-07"
        rpy="0 0 0" />
      <mass
        value="0.049567" />
      <inertia
        ixx="5.5979E-06"
        ixy="7.0496E-12"
        ixz="-3.8174E-12"
        iyy="7.5627E-06"
        iyz="6.331E-12"
        izz="5.5979E-06" />
    </inertial>
    <visual>
      <origin
        xyz="0 0 0"
        rpy="0 0 0" />
      <geometry>
        <mesh
          filename="package://bogie_description/meshes/wheel_1_link.STL" />
      </geometry>
      <material
        name="">
        <color
          rgba="0.79216 0.81961 0.93333 1" />
      </material>
    </visual>
    <collision>
      <origin
        xyz="0 0 0"
        rpy="0 0 0" />
      <geometry>
        <mesh
          filename="package://bogie_description/meshes/wheel_1_link.STL" />
      </geometry>
    </collision>
  </link>
  <joint
    name="wheel_1_joint"
    type="continuous">
    <origin
      xyz="0.19 0.125 0.021"
      rpy="0 0 0" />
    <parent
      link="base_link" />
    <child
      link="wheel_1_link" />
    <axis
      xyz="0 1 0" />
    <limit
      effort="10"
      velocity="10" />
    <dynamics
      damping="0.1"
      friction="0.1" />
  </joint>
  <link
    name="wheel_2_Link">
    <inertial>
      <origin
        xyz="3.094E-08 0.00012531 2.3359E-08"
        rpy="0 0 0" />
      <mass
        value="0.049561" />
      <inertia
        ixx="5.5972E-06"
        ixy="2.8674E-12"
        ixz="-6.0887E-12"
        iyy="7.5613E-06"
        iyz="1.7436E-12"
        izz="5.5972E-06" />
    </inertial>
    <visual>
      <origin
        xyz="0 0 0"
        rpy="0 0 0" />
      <geometry>
        <mesh
          filename="package://bogie_description/meshes/wheel_2_Link.STL" />
      </geometry>
      <material
        name="">
        <color
          rgba="0.79216 0.81961 0.93333 1" />
      </material>
    </visual>
    <collision>
      <origin
        xyz="0 0 0"
        rpy="0 0 0" />
      <geometry>
        <mesh
          filename="package://bogie_description/meshes/wheel_2_Link.STL" />
      </geometry>
    </collision>
  </link>
  <joint
    name="wheel_2_joint"
    type="continuous">
    <origin
      xyz="0.19 -0.125 0.021"
      rpy="0 0 0" />
    <parent
      link="base_link" />
    <child
      link="wheel_2_Link" />
    <axis
      xyz="0 -1 0" />
    <limit
      effort="10"
      velocity="10" />
    <dynamics
      damping="0.1"
      friction="0.1" />
  </joint>
  <link
    name="wheel_3_Link">
    <inertial>
      <origin
        xyz="3.094E-08 0.00012531 2.3358E-08"
        rpy="0 0 0" />
      <mass
        value="0.049561" />
      <inertia
        ixx="5.5972E-06"
        ixy="2.8674E-12"
        ixz="-6.0887E-12"
        iyy="7.5613E-06"
        iyz="1.7436E-12"
        izz="5.5972E-06" />
    </inertial>
    <visual>
      <origin
        xyz="0 0 0"
        rpy="0 0 0" />
      <geometry>
        <mesh
          filename="package://bogie_description/meshes/wheel_3_Link.STL" />
      </geometry>
      <material
        name="">
        <color
          rgba="0.79216 0.81961 0.93333 1" />
      </material>
    </visual>
    <collision>
      <origin
        xyz="0 0 0"
        rpy="0 0 0" />
      <geometry>
        <mesh
          filename="package://bogie_description/meshes/wheel_3_Link.STL" />
      </geometry>
    </collision>
  </link>
  <joint
    name="wheel_3_joint"
    type="continuous">
    <origin
      xyz="-0.19 0.125 0.021"
      rpy="0 0 0" />
    <parent
      link="base_link" />
    <child
      link="wheel_3_Link" />
    <axis
      xyz="0 1 0" />
    <limit
      effort="10"
      velocity="10" />
    <dynamics
      damping="0.1"
      friction="0.1" />
  </joint>
  <link
    name="wheel_4_Link">
    <inertial>
      <origin
        xyz="-2.1645E-08 0.00016001 -1.065E-07"
        rpy="0 0 0" />
      <mass
        value="0.049567" />
      <inertia
        ixx="5.5979E-06"
        ixy="7.0496E-12"
        ixz="-3.8174E-12"
        iyy="7.5627E-06"
        iyz="6.331E-12"
        izz="5.5979E-06" />
    </inertial>
    <visual>
      <origin
        xyz="0 0 0"
        rpy="0 0 0" />
      <geometry>
        <mesh
          filename="package://bogie_description/meshes/wheel_4_Link.STL" />
      </geometry>
      <material
        name="">
        <color
          rgba="0.79216 0.81961 0.93333 1" />
      </material>
    </visual>
    <collision>
      <origin
        xyz="0 0 0"
        rpy="0 0 0" />
      <geometry>
        <mesh
          filename="package://bogie_description/meshes/wheel_4_Link.STL" />
      </geometry>
    </collision>
  </link>
  <joint
    name="wheel_4_joint"
    type="continuous">
    <origin
      xyz="-0.19 -0.125 0.021"
      rpy="0 0 0" />
    <parent
      link="base_link" />
    <child
      link="wheel_4_Link" />
    <axis
      xyz="0 -1 0" />
    <limit
      effort="10"
      velocity="10" />
    <dynamics
      damping="0.1"
      friction="0.1" />
  </joint>
  <link
    name="base_laser_Link">
    <inertial>
      <origin
        xyz="0 0 0.0091"
        rpy="0 0 0" />
      <mass
        value="0.040153" />
      <inertia
        ixx="8.1576E-06"
        ixy="4.4841E-38"
        ixz="-1.2847E-22"
        iyy="8.1576E-06"
        iyz="4.2244E-38"
        izz="1.4099E-05" />
    </inertial>
    <visual>
      <origin
        xyz="0 0 0"
        rpy="0 0 0" />
      <geometry>
        <mesh
          filename="package://bogie_description/meshes/base_laser_Link.STL" />
      </geometry>
      <material
        name="">
        <color
          rgba="0.53725 0.53725 0.53725 1" />
      </material>
    </visual>
    <collision>
      <origin
        xyz="0 0 0"
        rpy="0 0 0" />
      <geometry>
        <mesh
          filename="package://bogie_description/meshes/base_laser_Link.STL" />
      </geometry>
    </collision>
  </link>
  <joint
    name="base_laser_joint"
    type="fixed">
    <origin
      xyz="0.15 0 0.195"
      rpy="0 0 0" />
    <parent
      link="base_link" />
    <child
      link="base_laser_Link" />
    <axis
      xyz="0 0 0" />
  </joint>

<link name="imu_link">
  <inertial>
    <origin xyz="0.0 0.0 -0.0050000000000000044" rpy="0 0 0"/>
    <mass value="0.0037199999999999998"/>
    <inertia ixx="0.0" iyy="0.0" izz="0.0" ixy="0.0" iyz="0.0" ixz="0.0"/>
  </inertial>
  <visual>
    <origin xyz="0.095 -0.0 -0.2875" rpy="0 0 0"/>
    <geometry>
      <mesh filename="package://bogie_description/meshes/imu_link.STL" scale="0.001 0.001 0.001"/>
    </geometry>
    <material name="silver"/>
  </visual>
  <collision>
    <origin xyz="0.095 -0.0 -0.2875" rpy="0 0 0"/>
    <geometry>
      <mesh filename="package://bogie_description/meshes/imu_link.STL" scale="0.001 0.001 0.001"/>
    </geometry>
  </collision>
</link>

  <joint
    name="imu_joint"
    type="fixed">
    <origin
      xyz="0.15 0 0.14"
      rpy="0 0 0" />
    <parent
      link="base_link" />
    <child
      link="imu_link" />
    <axis
      xyz="0 0 0" />
  </joint>
</robot>